2025-10-03 18:48:23,894Z [INFO] [run:20251003-184823] [connector:-] attempt=0 environment
2025-10-03 18:48:23,895Z [INFO] [run:20251003-184823] [connector:-] attempt=0 parsed arguments
2025-10-03 18:48:23,942Z [INFO] [run:20251003-184823] [connector:-] attempt=0 planning run
2025-10-03 18:48:23,943Z [INFO] [run:20251003-184823] [connector:ifrc_go_client] attempt=1 starting
2025-10-03 18:48:40,409Z [INFO] [run:20251003-184823] [connector:ifrc_go_client] attempt=1 completed
2025-10-03 18:48:40,410Z [INFO] [run:20251003-184823] [connector:ifrc_go_client] attempt=0 finished
2025-10-03 18:48:40,418Z [INFO] [run:20251003-184823] [connector:reliefweb_client] attempt=1 starting
2025-10-03 18:49:03,980Z [INFO] [run:20251003-184823] [connector:reliefweb_client] attempt=1 completed
2025-10-03 18:49:03,980Z [INFO] [run:20251003-184823] [connector:reliefweb_client] attempt=0 finished
2025-10-03 18:49:03,988Z [INFO] [run:20251003-184823] [connector:unhcr_client] attempt=1 starting
2025-10-03 18:49:39,086Z [INFO] [run:20251003-184823] [connector:unhcr_client] attempt=1 completed
2025-10-03 18:49:39,086Z [INFO] [run:20251003-184823] [connector:unhcr_client] attempt=0 finished
2025-10-03 18:49:39,087Z [INFO] [run:20251003-184823] [connector:unhcr_odp_client] attempt=1 starting
2025-10-03 18:49:49,300Z [INFO] [run:20251003-184823] [connector:unhcr_odp_client] attempt=1 completed
2025-10-03 18:49:49,300Z [INFO] [run:20251003-184823] [connector:unhcr_odp_client] attempt=0 finished
2025-10-03 18:49:49,301Z [INFO] [run:20251003-184823] [connector:who_phe_client] attempt=1 starting
2025-10-03 18:49:49,909Z [INFO] [run:20251003-184823] [connector:who_phe_client] attempt=1 completed
2025-10-03 18:49:49,909Z [INFO] [run:20251003-184823] [connector:who_phe_client] attempt=0 finished
2025-10-03 18:49:49,910Z [INFO] [run:20251003-184823] [connector:ipc_client] attempt=1 starting
2025-10-03 18:49:50,270Z [WARNING] [run:20251003-184823] [connector:ipc_client] attempt=0 attempt failed
Traceback (most recent call last):
  File "C:\GitHub\Forecaster\resolver\ingestion\_retry.py", line 62, in retry_call
    result = func(attempt)
  File "C:\GitHub\Forecaster\resolver\ingestion\run_all_stubs.py", line 663, in _attempt
    return _run_connector(spec, attempt_logger)
  File "C:\GitHub\Forecaster\resolver\ingestion\run_all_stubs.py", line 477, in _run_connector
    _invoke_connector(spec.path)
    ~~~~~~~~~~~~~~~~~^^^^^^^^^^^
  File "C:\GitHub\Forecaster\resolver\ingestion\run_all_stubs.py", line 428, in _invoke_connector
    raise subprocess.CalledProcessError(proc.returncode, [sys.executable, str(path)])
subprocess.CalledProcessError: Command '['C:\\GitHub\\Forecaster\\.venv\\Scripts\\python.exe', 'C:\\GitHub\\Forecaster\\resolver\\ingestion\\ipc_client.py']' returned non-zero exit status 1.
2025-10-03 18:49:51,558Z [INFO] [run:20251003-184823] [connector:ipc_client] attempt=2 starting
2025-10-03 18:49:51,967Z [WARNING] [run:20251003-184823] [connector:ipc_client] attempt=0 attempt failed
Traceback (most recent call last):
  File "C:\GitHub\Forecaster\resolver\ingestion\_retry.py", line 62, in retry_call
    result = func(attempt)
  File "C:\GitHub\Forecaster\resolver\ingestion\run_all_stubs.py", line 663, in _attempt
    return _run_connector(spec, attempt_logger)
  File "C:\GitHub\Forecaster\resolver\ingestion\run_all_stubs.py", line 477, in _run_connector
    _invoke_connector(spec.path)
    ~~~~~~~~~~~~~~~~~^^^^^^^^^^^
  File "C:\GitHub\Forecaster\resolver\ingestion\run_all_stubs.py", line 428, in _invoke_connector
    raise subprocess.CalledProcessError(proc.returncode, [sys.executable, str(path)])
subprocess.CalledProcessError: Command '['C:\\GitHub\\Forecaster\\.venv\\Scripts\\python.exe', 'C:\\GitHub\\Forecaster\\resolver\\ingestion\\ipc_client.py']' returned non-zero exit status 1.
2025-10-03 18:49:51,968Z [ERROR] [run:20251003-184823] [connector:ipc_client] attempt=0 failed
Traceback (most recent call last):
  File "C:\GitHub\Forecaster\resolver\ingestion\run_all_stubs.py", line 686, in main
    result = retry_call(
        _attempt,
    ...<6 lines>...
        is_retryable=_should_retry,
    )
  File "C:\GitHub\Forecaster\resolver\ingestion\_retry.py", line 62, in retry_call
    result = func(attempt)
  File "C:\GitHub\Forecaster\resolver\ingestion\run_all_stubs.py", line 663, in _attempt
    return _run_connector(spec, attempt_logger)
  File "C:\GitHub\Forecaster\resolver\ingestion\run_all_stubs.py", line 477, in _run_connector
    _invoke_connector(spec.path)
    ~~~~~~~~~~~~~~~~~^^^^^^^^^^^
  File "C:\GitHub\Forecaster\resolver\ingestion\run_all_stubs.py", line 428, in _invoke_connector
    raise subprocess.CalledProcessError(proc.returncode, [sys.executable, str(path)])
subprocess.CalledProcessError: Command '['C:\\GitHub\\Forecaster\\.venv\\Scripts\\python.exe', 'C:\\GitHub\\Forecaster\\resolver\\ingestion\\ipc_client.py']' returned non-zero exit status 1.
2025-10-03 18:49:51,970Z [INFO] [run:20251003-184823] [connector:wfp_mvam_client] attempt=1 starting
2025-10-03 18:49:52,554Z [WARNING] [run:20251003-184823] [connector:wfp_mvam_client] attempt=0 attempt failed
Traceback (most recent call last):
  File "C:\GitHub\Forecaster\resolver\ingestion\_retry.py", line 62, in retry_call
    result = func(attempt)
  File "C:\GitHub\Forecaster\resolver\ingestion\run_all_stubs.py", line 663, in _attempt
    return _run_connector(spec, attempt_logger)
  File "C:\GitHub\Forecaster\resolver\ingestion\run_all_stubs.py", line 477, in _run_connector
    _invoke_connector(spec.path)
    ~~~~~~~~~~~~~~~~~^^^^^^^^^^^
  File "C:\GitHub\Forecaster\resolver\ingestion\run_all_stubs.py", line 428, in _invoke_connector
    raise subprocess.CalledProcessError(proc.returncode, [sys.executable, str(path)])
subprocess.CalledProcessError: Command '['C:\\GitHub\\Forecaster\\.venv\\Scripts\\python.exe', 'C:\\GitHub\\Forecaster\\resolver\\ingestion\\wfp_mvam_client.py']' returned non-zero exit status 1.
2025-10-03 18:49:53,600Z [INFO] [run:20251003-184823] [connector:wfp_mvam_client] attempt=2 starting
2025-10-03 18:49:54,172Z [WARNING] [run:20251003-184823] [connector:wfp_mvam_client] attempt=0 attempt failed
Traceback (most recent call last):
  File "C:\GitHub\Forecaster\resolver\ingestion\_retry.py", line 62, in retry_call
    result = func(attempt)
  File "C:\GitHub\Forecaster\resolver\ingestion\run_all_stubs.py", line 663, in _attempt
    return _run_connector(spec, attempt_logger)
  File "C:\GitHub\Forecaster\resolver\ingestion\run_all_stubs.py", line 477, in _run_connector
    _invoke_connector(spec.path)
    ~~~~~~~~~~~~~~~~~^^^^^^^^^^^
  File "C:\GitHub\Forecaster\resolver\ingestion\run_all_stubs.py", line 428, in _invoke_connector
    raise subprocess.CalledProcessError(proc.returncode, [sys.executable, str(path)])
subprocess.CalledProcessError: Command '['C:\\GitHub\\Forecaster\\.venv\\Scripts\\python.exe', 'C:\\GitHub\\Forecaster\\resolver\\ingestion\\wfp_mvam_client.py']' returned non-zero exit status 1.
2025-10-03 18:49:54,174Z [ERROR] [run:20251003-184823] [connector:wfp_mvam_client] attempt=0 failed
Traceback (most recent call last):
  File "C:\GitHub\Forecaster\resolver\ingestion\run_all_stubs.py", line 686, in main
    result = retry_call(
        _attempt,
    ...<6 lines>...
        is_retryable=_should_retry,
    )
  File "C:\GitHub\Forecaster\resolver\ingestion\_retry.py", line 62, in retry_call
    result = func(attempt)
  File "C:\GitHub\Forecaster\resolver\ingestion\run_all_stubs.py", line 663, in _attempt
    return _run_connector(spec, attempt_logger)
  File "C:\GitHub\Forecaster\resolver\ingestion\run_all_stubs.py", line 477, in _run_connector
    _invoke_connector(spec.path)
    ~~~~~~~~~~~~~~~~~^^^^^^^^^^^
  File "C:\GitHub\Forecaster\resolver\ingestion\run_all_stubs.py", line 428, in _invoke_connector
    raise subprocess.CalledProcessError(proc.returncode, [sys.executable, str(path)])
subprocess.CalledProcessError: Command '['C:\\GitHub\\Forecaster\\.venv\\Scripts\\python.exe', 'C:\\GitHub\\Forecaster\\resolver\\ingestion\\wfp_mvam_client.py']' returned non-zero exit status 1.
2025-10-03 18:49:54,176Z [INFO] [run:20251003-184823] [connector:acled_client] attempt=1 starting
2025-10-03 18:49:54,773Z [WARNING] [run:20251003-184823] [connector:acled_client] attempt=0 attempt failed
Traceback (most recent call last):
  File "C:\GitHub\Forecaster\resolver\ingestion\_retry.py", line 62, in retry_call
    result = func(attempt)
  File "C:\GitHub\Forecaster\resolver\ingestion\run_all_stubs.py", line 663, in _attempt
    return _run_connector(spec, attempt_logger)
  File "C:\GitHub\Forecaster\resolver\ingestion\run_all_stubs.py", line 477, in _run_connector
    _invoke_connector(spec.path)
    ~~~~~~~~~~~~~~~~~^^^^^^^^^^^
  File "C:\GitHub\Forecaster\resolver\ingestion\run_all_stubs.py", line 428, in _invoke_connector
    raise subprocess.CalledProcessError(proc.returncode, [sys.executable, str(path)])
subprocess.CalledProcessError: Command '['C:\\GitHub\\Forecaster\\.venv\\Scripts\\python.exe', 'C:\\GitHub\\Forecaster\\resolver\\ingestion\\acled_client.py']' returned non-zero exit status 1.
2025-10-03 18:49:56,007Z [INFO] [run:20251003-184823] [connector:acled_client] attempt=2 starting
2025-10-03 18:49:56,598Z [WARNING] [run:20251003-184823] [connector:acled_client] attempt=0 attempt failed
Traceback (most recent call last):
  File "C:\GitHub\Forecaster\resolver\ingestion\_retry.py", line 62, in retry_call
    result = func(attempt)
  File "C:\GitHub\Forecaster\resolver\ingestion\run_all_stubs.py", line 663, in _attempt
    return _run_connector(spec, attempt_logger)
  File "C:\GitHub\Forecaster\resolver\ingestion\run_all_stubs.py", line 477, in _run_connector
    _invoke_connector(spec.path)
    ~~~~~~~~~~~~~~~~~^^^^^^^^^^^
  File "C:\GitHub\Forecaster\resolver\ingestion\run_all_stubs.py", line 428, in _invoke_connector
    raise subprocess.CalledProcessError(proc.returncode, [sys.executable, str(path)])
subprocess.CalledProcessError: Command '['C:\\GitHub\\Forecaster\\.venv\\Scripts\\python.exe', 'C:\\GitHub\\Forecaster\\resolver\\ingestion\\acled_client.py']' returned non-zero exit status 1.
2025-10-03 18:49:56,600Z [ERROR] [run:20251003-184823] [connector:acled_client] attempt=0 failed
Traceback (most recent call last):
  File "C:\GitHub\Forecaster\resolver\ingestion\run_all_stubs.py", line 686, in main
    result = retry_call(
        _attempt,
    ...<6 lines>...
        is_retryable=_should_retry,
    )
  File "C:\GitHub\Forecaster\resolver\ingestion\_retry.py", line 62, in retry_call
    result = func(attempt)
  File "C:\GitHub\Forecaster\resolver\ingestion\run_all_stubs.py", line 663, in _attempt
    return _run_connector(spec, attempt_logger)
  File "C:\GitHub\Forecaster\resolver\ingestion\run_all_stubs.py", line 477, in _run_connector
    _invoke_connector(spec.path)
    ~~~~~~~~~~~~~~~~~^^^^^^^^^^^
  File "C:\GitHub\Forecaster\resolver\ingestion\run_all_stubs.py", line 428, in _invoke_connector
    raise subprocess.CalledProcessError(proc.returncode, [sys.executable, str(path)])
subprocess.CalledProcessError: Command '['C:\\GitHub\\Forecaster\\.venv\\Scripts\\python.exe', 'C:\\GitHub\\Forecaster\\resolver\\ingestion\\acled_client.py']' returned non-zero exit status 1.
2025-10-03 18:49:56,602Z [INFO] [run:20251003-184823] [connector:dtm_client] attempt=1 starting
2025-10-03 18:49:56,970Z [INFO] [run:20251003-184823] [connector:dtm_client] attempt=1 completed
2025-10-03 18:49:56,970Z [INFO] [run:20251003-184823] [connector:dtm_client] attempt=0 finished
2025-10-03 18:49:56,971Z [INFO] [run:20251003-184823] [connector:hdx_client] attempt=1 starting
2025-10-03 18:49:57,565Z [WARNING] [run:20251003-184823] [connector:hdx_client] attempt=0 attempt failed
Traceback (most recent call last):
  File "C:\GitHub\Forecaster\resolver\ingestion\_retry.py", line 62, in retry_call
    result = func(attempt)
  File "C:\GitHub\Forecaster\resolver\ingestion\run_all_stubs.py", line 663, in _attempt
    return _run_connector(spec, attempt_logger)
  File "C:\GitHub\Forecaster\resolver\ingestion\run_all_stubs.py", line 477, in _run_connector
    _invoke_connector(spec.path)
    ~~~~~~~~~~~~~~~~~^^^^^^^^^^^
  File "C:\GitHub\Forecaster\resolver\ingestion\run_all_stubs.py", line 428, in _invoke_connector
    raise subprocess.CalledProcessError(proc.returncode, [sys.executable, str(path)])
subprocess.CalledProcessError: Command '['C:\\GitHub\\Forecaster\\.venv\\Scripts\\python.exe', 'C:\\GitHub\\Forecaster\\resolver\\ingestion\\hdx_client.py']' returned non-zero exit status 1.
2025-10-03 18:49:58,852Z [INFO] [run:20251003-184823] [connector:hdx_client] attempt=2 starting
2025-10-03 18:49:59,444Z [WARNING] [run:20251003-184823] [connector:hdx_client] attempt=0 attempt failed
Traceback (most recent call last):
  File "C:\GitHub\Forecaster\resolver\ingestion\_retry.py", line 62, in retry_call
    result = func(attempt)
  File "C:\GitHub\Forecaster\resolver\ingestion\run_all_stubs.py", line 663, in _attempt
    return _run_connector(spec, attempt_logger)
  File "C:\GitHub\Forecaster\resolver\ingestion\run_all_stubs.py", line 477, in _run_connector
    _invoke_connector(spec.path)
    ~~~~~~~~~~~~~~~~~^^^^^^^^^^^
  File "C:\GitHub\Forecaster\resolver\ingestion\run_all_stubs.py", line 428, in _invoke_connector
    raise subprocess.CalledProcessError(proc.returncode, [sys.executable, str(path)])
subprocess.CalledProcessError: Command '['C:\\GitHub\\Forecaster\\.venv\\Scripts\\python.exe', 'C:\\GitHub\\Forecaster\\resolver\\ingestion\\hdx_client.py']' returned non-zero exit status 1.
2025-10-03 18:49:59,445Z [ERROR] [run:20251003-184823] [connector:hdx_client] attempt=0 failed
Traceback (most recent call last):
  File "C:\GitHub\Forecaster\resolver\ingestion\run_all_stubs.py", line 686, in main
    result = retry_call(
        _attempt,
    ...<6 lines>...
        is_retryable=_should_retry,
    )
  File "C:\GitHub\Forecaster\resolver\ingestion\_retry.py", line 62, in retry_call
    result = func(attempt)
  File "C:\GitHub\Forecaster\resolver\ingestion\run_all_stubs.py", line 663, in _attempt
    return _run_connector(spec, attempt_logger)
  File "C:\GitHub\Forecaster\resolver\ingestion\run_all_stubs.py", line 477, in _run_connector
    _invoke_connector(spec.path)
    ~~~~~~~~~~~~~~~~~^^^^^^^^^^^
  File "C:\GitHub\Forecaster\resolver\ingestion\run_all_stubs.py", line 428, in _invoke_connector
    raise subprocess.CalledProcessError(proc.returncode, [sys.executable, str(path)])
subprocess.CalledProcessError: Command '['C:\\GitHub\\Forecaster\\.venv\\Scripts\\python.exe', 'C:\\GitHub\\Forecaster\\resolver\\ingestion\\hdx_client.py']' returned non-zero exit status 1.
2025-10-03 18:49:59,447Z [INFO] [run:20251003-184823] [connector:emdat_client] attempt=1 starting
2025-10-03 18:50:00,546Z [INFO] [run:20251003-184823] [connector:emdat_client] attempt=1 completed
2025-10-03 18:50:00,546Z [INFO] [run:20251003-184823] [connector:emdat_client] attempt=0 finished
2025-10-03 18:50:00,547Z [INFO] [run:20251003-184823] [connector:gdacs_client] attempt=1 starting
2025-10-03 18:50:01,211Z [INFO] [run:20251003-184823] [connector:gdacs_client] attempt=1 completed
2025-10-03 18:50:01,212Z [INFO] [run:20251003-184823] [connector:gdacs_client] attempt=0 finished
2025-10-03 18:50:01,213Z [INFO] [run:20251003-184823] [connector:worldpop_client] attempt=1 starting
2025-10-03 18:50:01,864Z [INFO] [run:20251003-184823] [connector:worldpop_client] attempt=1 completed
2025-10-03 18:50:01,865Z [INFO] [run:20251003-184823] [connector:worldpop_client] attempt=0 finished
2025-10-03 18:50:01,865Z [INFO] [run:20251003-184823] [connector:-] attempt=0 Connector summary
Connector        | Status   | Attempts | Rows | Duration(ms) | Notes                                                                                                                                                         
-----------------+----------+----------+------+--------------+---------------------------------------------------------------------------------------------------------------------------------------------------------------
ifrc_go_client   | ok       | 1        | 0    | 16473        |                                                                                                                                                               
reliefweb_client | ok       | 1        | 0    | 23562        |                                                                                                                                                               
unhcr_client     | ok-empty | 1        | 0    | 35098        | header-only                                                                                                                                                   
unhcr_odp_client | ok-empty | 1        | 0    | 10213        | header-only                                                                                                                                                   
who_phe_client   | ok-empty | 1        | 0    | 608          | header-only                                                                                                                                                   
ipc_client       | error    | 2        | 0    | 2059         | Command '['C:\\GitHub\\Forecaster\\.venv\\Scripts\\python.exe', 'C:\\GitHub\\Forecaster\\resolver\\ingestion\\ipc_client.py']' returned non-zero exit status 1.     
wfp_mvam_client  | error    | 2        | 0    | 2205         | Command '['C:\\GitHub\\Forecaster\\.venv\\Scripts\\python.exe', 'C:\\GitHub\\Forecaster\\resolver\\ingestion\\wfp_mvam_client.py']' returned non-zero exit status 1.
acled_client     | error    | 2        | 0    | 2425         | Command '['C:\\GitHub\\Forecaster\\.venv\\Scripts\\python.exe', 'C:\\GitHub\\Forecaster\\resolver\\ingestion\\acled_client.py']' returned non-zero exit status 1.   
dtm_client       | ok-empty | 1        | 0    | 368          | header-only                                                                                                                                                   
hdx_client       | error    | 2        | 0    | 2475         | Command '['C:\\GitHub\\Forecaster\\.venv\\Scripts\\python.exe', 'C:\\GitHub\\Forecaster\\resolver\\ingestion\\hdx_client.py']' returned non-zero exit status 1.     
emdat_client     | ok       | 1        | 0    | 1099         |                                                                                                                                                               
gdacs_client     | ok       | 1        | 0    | 665          |                                                                                                                                                               
worldpop_client  | ok       | 1        | 0    | 652          |                                                                                                                                                               
2025-10-03 18:50:01,865Z [INFO] [run:20251003-184823] [connector:-] attempt=0 run complete
